Workbook

Sheet All 
A1: Std ID | B1: Name | C1: Course Name | D1: Current Topic | E1: Progress | F1: beginning date | G1: Validity | H1: Staff | I1: Presentation | J1: Date | K1: Status
A2: TDAM001 | B2: Ameesha | C2: MERN | D2: Django | E2: Authentication | G2: 46249 | H2: Abin Raj | I2: Virtual Reality and Augmented Reality
A3: TDAM002 | B3: Rahees PK | C3: MERN | D3: Completed | E3: interceptor | G3: 46233 | H3: Ameer | I3: Robotics and Automation
A4: TDAM003 | B4: Hisham | C4: MERN | D4: MongoDB | E4: interceptor | G4: 46233 | H4: Ameer | I4: Cloud Computing and Its Benefits | J4: 46213 | K4: Done
A5: TDAM004 | B5: Harshal | C5: MERN | D5: MongoDB | E5: interceptor | G5: 46233 | H5: Ameer | I5: Internet of Things: Smart Devices Around Us | J5: 46216
A6: TDAM005 | B6: M. Danish | C6: MERN | D6: mongodb | E6: start | G6: 46233 | H6: Ameer | I6: Artificial Intelligence in Healthcare
A7: TDAM006 | B7: M. Safeer | C7: MERN | D7: react | E7: react | G7: 46249 | H7: Ameer | I7: =_xlfn.XLOOKUP(G5,'All '!B2:B21,"Not Available") -> #VALUE! | J7: 46212 | K7: Done
A8: TDAM007 | B8: Nibrasul Haqu C | C8: MERN | D8: React | E8: intro | G8: 46249 | H8: Ameer | I8: Zustand, File Upload | J8: 46210 | K8: Done
A9: TDAM008 | B9: Aswin KC | C9: MERN | D9: CSS | E9: Clone | G9: 46387 | H9: Ameer | I9: Blockchain Technology and Cryptocurrency | J9: 46220 | K9: Done
A10: TDAM009 | B10: Abinav | C10: MERN | D10: CSS | E10: Clone | G10: 46387 | H10: Ameer | I10: Machine Learning in Daily Life | J10: 46220 | K10: Done
A11: TDAM010 | B11: M Sinan | C11: MERN | D11: HTML | E11: intro | G11: 46387 | H11: Aswin KP | I11: Ethical Hacking and Penetration Testing | J11: 46220 | K11: Done
A12: TDAP001 | B12: M Nasif | C12: Python | D12: HTML | E12: intro | G12: 46387 | H12: Aswin KP | I12: Ethical Hacking and Penetration Testing | J12: 46219
A13: TDAP002 | B13: Suhail | C13: Python | D13: python | E13: intro | G13: 46387 | H13: Aswin KP | I13: Role of Technology in Education
A14: TDAF001 | B14: Safwan | C14: Python Flutter | D14: python | E14: intro | G14: 46387 | H14: Aswin KP | I14: Digital Transformation in Business
A15: TDAF002 | B15: Muhammed Shahid | C15: Python Flutter | H15: Shameem | I15: Web Development: Past, Present, and Future
A16: TDAF003 | B16: Hudha Reema | C16: python flutter | H16: Shameem | I16: Big Data and Data Analytics
A17: TDAF004 | B17: Muhammed Munaver V P | C17: python flutter | G17: 46387 | H17: Shameem
A18: TDAF005 | B18: M.Shebil | C18: Python Flutter-Django | D18: flutter | E18: basic | G18: 46387 | H18: Shameem | I18: E-Commerce and Online Payment Security
A19: TDAN001 | B19: M. Shabeeb | C19: Python Next js | G19: 46387 | H19: Vishnu | I19: Zero Trust Model | J19: 46211 | K19: Done
A20: TDAN002 | B20: Rifana | C20: Python Next js | D20: c p | G20: 46387 | H20: Aswin KP
A21: TDAA001 | B21: Ajmal | C21: PythonDjango-Angular | D21: Angular | E21: Advanced | G21: 46233 | H21: Ameer | I21: Artificial Intelligence in Healthcare
A22: TDAA002 | B22: Ameera K | C22: PythonDjango-Angular | D22: Python | E22: patterns | G22: 46336 | H22: Jan Sabith | I22: Green Technology and Sustainable IT
A23: TDAA003 | B23: Nidhal Muhammad PC | C23: PythonDjango-Angular | D23: Python | E23: file handling | G23: 46337 | H23: Jan Sabith | I23: Web3 | J23: 46211 | K23: Done
A24: TDAR001 | B24: M Shameel | C24: PythonDjango-React | D24: React | E24: completed | G24: 46233 | H24: Aswin PP | I24: Smart Homes and Home Automation | J24: 46217
A25: TDAR002 | B25: M. Shamil TK | C25: PythonDjango-React | D25: React | E25: completed | G25: 46233 | H25: Aswin PP | I25: Drone Technology and Its Applications
A26: TDAR003 | B26: M. Muaad | C26: PythonDjango-React | D26: React | E26: completed | G26: 46233 | H26: Vishnu | I26: Cybercrime and How to Prevent It | J26: 46216 | K26: Done
A27: TDAR004 | B27: M. Nihal | C27: PythonDjango-React | D27: React | E27: completed | G27: 46233 | H27: Abin Raj | I27: Wearable Technology in Daily Life | J27: 46216 | K27: Done
A28: TDAR005 | B28: M. Ajmal CP | C28: PythonDjango-React | D28: react | E28: DOM | G28: 46249 | H28: Anandu | I28: Social Media and Its Impact on Society
A29: TDAR006 | B29: M. Rameesh KP | C29: PythonDjango-React | D29: react | E29: DOM | G29: 46249 | H29: Anandu | I29: Cloud Storage vs Local Storage
A30: TDAR007 | B30: M. Irfan H | C30: PythonDjango-React | D30: react | E30: api f | G30: 46249 | H30: Anandu | I30: Quantum Computing: The Next Big Revolution
A31: TDAR008 | B31: Sajeer Fasil | C31: PythonDjango-React | D31: react | E31: router | G31: 46249 | H31: Abin Raj | I31: Operating Systems: Windows, Linux, and macOS
A32: TDAR009 | B32: Raneed | C32: PythonDjango-React | D32: react | E32: DOM | G32: 46249 | H32: Abin Raj | I32: Internet Safety for Students
A33: TDAR010 | B33: Ashil | C33: PythonDjango-React | D33: react | E33: DOM | G33: 46249 | H33: Jan Sabith | I33: Digital Marketing and Technology | J33: 46213 | K33: Done
A34: TDAR011 | B34: Muhammed Rashid T | C34: PythonDjango-React | D34: React | E34: intro | G34: 46249 | H34: Aswin PP | I34: Technology in Agriculture
A35: TDAR012 | B35: M. Jamshid | C35: PythonDjango-React | D35: html | E35: intro | G35: 46265 | H35: Vishnu | I35: Smart Cities and Technology
A36: TDAR013 | B36: M. Irfan K | C36: PythonDjango-React | D36: html | E36: intro | G36: 46265 | H36: Anandu | I36: Importance of IT Support in Organizations
A37: TDAR014 | B37: Nihal Roshan | C37: PythonDjango-React | D37: html | E37: intro | G37: 46265 | H37: Anandu | I37: Django - Django REST framework
A38: TDAR015 | B38: Fadhil | C38: PythonDjango-React | D38: html | E38: intro | G38: 46265 | H38: Jan Sabith | I38: Deepfake Technology: Benefits and Risks | J38: 46213
A39: TDAR016 | B39: Abdul Sabith SB | C39: PythonDjango-React | D39: html | E39: intro | G39: 46265 | H39: Vishnu | I39: HTML | J39: 46220
A40: TDAR017 | B40: Abu Hashim | C40: PythonDjango-React | D40: html | E40: intro | G40: 46265 | H40: Anandu | I40: Digital Banking and FinTech Innovation
...

Sheet Review History
A1: Std ID | B1: Name | C1: Course Name | D1: Review no | E1: Review Date | F1: Mark | G1: Status | H1: Trainer
A2: =_xlfn.XLOOKUP(B2,'All '!B:B,'All '!A:A,"No Found") -> TDAA001 | B2: Ajmal | C2: PythonDjango-Angular | D2: 1 | E2: 46182 | F2: 7 | G2: =IF(F2="","Pending",IF(F2<7,"Weekback","No Weekback")) -> No Weekback | J2: {=IFERROR(_xlfn._xlws.SORT(_xlfn.UNIQUE(_xlfn._xlws.FILTER('Review History'!D:D,'Review History'!B:B=Dashboard.!F5))),0)} -> 1
A3: =_xlfn.XLOOKUP(B3,'All '!B:B,'All '!A:A,"No Found") -> TDAM002 | B3: Rahees PK | C3: MERN | D3: =COUNTIF($B$3:B23,B3) -> 1 | E3: 46182 | F3: 5 | G3: =IF(F3="","Pending",IF(F3<7,"Weekback","No Weekback")) -> Weekback | J3: 2
A4: =_xlfn.XLOOKUP(B4,'All '!B:B,'All '!A:A,"No Found") -> TDAM003 | B4: Hisham | C4: MERN | D4: =COUNTIF($B$3:B24,B4) -> 1 | E4: 46182 | F4: 5 | G4: =IF(F4="","Pending",IF(F4<7,"Weekback","No Weekback")) -> Weekback
A5: =_xlfn.XLOOKUP(B5,'All '!B:B,'All '!A:A,"No Found") -> TDAM004 | B5: Harshal | C5: MERN | D5: =COUNTIF($B$3:B25,B5) -> 1 | E5: 46182 | F5: 6 | G5: =IF(F5="","Pending",IF(F5<7,"Weekback","No Weekback")) -> Weekback
A6: =_xlfn.XLOOKUP(B6,'All '!B:B,'All '!A:A,"No Found") -> TDAU001 | B6: Fathima Rafa | C6: UX-React | D6: =COUNTIF($B$3:B26,B6) -> 1 | E6: 46182 | F6: 7 | G6: =IF(F6="","Pending",IF(F6<7,"Weekback","No Weekback")) -> No Weekback
A7: =_xlfn.XLOOKUP(B7,'All '!B:B,'All '!A:A,"No Found") -> TDAU002 | B7: Fathima Safna | C7: UX-React | D7: =COUNTIF($B$3:B27,B7) -> 1 | E7: 46182 | F7: 2.3 | G7: =IF(F7="","Pending",IF(F7<7,"Weekback","No Weekback")) -> Weekback
A8: =_xlfn.XLOOKUP(B8,'All '!B:B,'All '!A:A,"No Found") -> TDAU003 | B8: Riswa Mehfin | C8: UX-React | D8: =COUNTIF($B$3:B28,B8) -> 1 | E8: 46182 | F8: 1.3 | G8: =IF(F8="","Pending",IF(F8<7,"Weekback","No Weekback")) -> Weekback
A9: =_xlfn.XLOOKUP(B9,'All '!B:B,'All '!A:A,"No Found") -> TDAU004 | B9: Faheem | C9: UX-React | D9: =COUNTIF($B$3:B29,B9) -> 1 | E9: 46182 | F9: 4 | G9: =IF(F9="","Pending",IF(F9<7,"Weekback","No Weekback")) -> Weekback | O9: +
A10: =_xlfn.XLOOKUP(B10,'All '!B:B,'All '!A:A,"No Found") -> TDAR002 | B10: M. Shamil TK | C10: PythonDjango-React | D10: =COUNTIF($B$3:B30,B10) -> 1 | E10: 46182 | F10: 3 | G10: =IF(F10="","Pending",IF(F10<7,"Weekback","No Weekback")) -> Weekback
A11: =_xlfn.XLOOKUP(B11,'All '!B:B,'All '!A:A,"No Found") -> TDAR003 | B11: M. Muaad | C11: PythonDjango-React | D11: =COUNTIF($B$3:B31,B11) -> 1 | E11: 46182 | F11: 6 | G11: =IF(F11="","Pending",IF(F11<7,"Weekback","No Weekback")) -> Weekback
A12: =_xlfn.XLOOKUP(B12,'All '!B:B,'All '!A:A,"No Found") -> TDAR005 | B12: M. Ajmal CP | C12: PythonDjango-React | D12: =COUNTIF($B$3:B32,B12) -> 1 | E12: 46182 | F12: 4 | G12: =IF(F12="","Pending",IF(F12<7,"Weekback","No Weekback")) -> Weekback
A13: =_xlfn.XLOOKUP(B13,'All '!B:B,'All '!A:A,"No Found") -> TDAR006 | B13: M. Rameesh KP | C13: PythonDjango-React | D13: =COUNTIF($B$3:B33,B13) -> 1 | E13: 46182 | F13: 3 | G13: =IF(F13="","Pending",IF(F13<7,"Weekback","No Weekback")) -> Weekback
A14: =_xlfn.XLOOKUP(B14,'All '!B:B,'All '!A:A,"No Found") -> TDAR007 | B14: M. Irfan H | C14: PythonDjango-React | D14: =COUNTIF($B$3:B34,B14) -> 1 | E14: 46182 | F14: 8 | G14: =IF(F14="","Pending",IF(F14<7,"Weekback","No Weekback")) -> No Weekback
A15: =_xlfn.XLOOKUP(B15,'All '!B:B,'All '!A:A,"No Found") -> TDAM006 | B15: M. Safeer | C15: MERN | D15: =COUNTIF($B$3:B35,B15) -> 1 | E15: 46182 | F15: 7 | G15: =IF(F15="","Pending",IF(F15<7,"Weekback","No Weekback")) -> No Weekback
A16: =_xlfn.XLOOKUP(B16,'All '!B:B,'All '!A:A,"No Found") -> TDAR009 | B16: Raneed | C16: PythonDjango-React | D16: =COUNTIF($B$3:B36,B16) -> 1 | E16: 46182 | F16: 4.5 | G16: =IF(F16="","Pending",IF(F16<7,"Weekback","No Weekback")) -> Weekback
A17: =_xlfn.XLOOKUP(B17,'All '!B:B,'All '!A:A,"No Found") -> TDAR010 | B17: Ashil | C17: PythonDjango-React | D17: =COUNTIF($B$3:B37,B17) -> 1 | E17: 46182 | F17: Resheduled | G17: =IF(F17="","Pending",IF(F17<7,"Weekback","No Weekback")) -> No Weekback
A18: =_xlfn.XLOOKUP(B18,'All '!B:B,'All '!A:A,"No Found") -> TDAM001 | B18: Ameesha | C18: Flutter-Django | D18: =COUNTIF($B$3:B38,B18) -> 1 | E18: 46182 | F18: 5 | G18: =IF(F18="","Pending",IF(F18<7,"Weekback","No Weekback")) -> Weekback
A19: =_xlfn.XLOOKUP(B19,'All '!B:B,'All '!A:A,"No Found") -> TDAM007 | B19: Nibrasul Haqu C | C19: MERN | D19: =COUNTIF($B$3:B39,B19) -> 1 | E19: 46182 | F19: 6 | G19: =IF(F19="","Pending",IF(F19<7,"Weekback","No Weekback")) -> Weekback
A20: =_xlfn.XLOOKUP(B20,'All '!B:B,'All '!A:A,"No Found") -> TDAR012 | B20: M. Jamshid | C20: PythonDjango-React | D20: =COUNTIF($B$3:B40,B20) -> 1 | E20: 46182 | F20: Resheduled | G20: =IF(F20="","Pending",IF(F20<7,"Weekback","No Weekback")) -> No Weekback
A21: =_xlfn.XLOOKUP(B21,'All '!B:B,'All '!A:A,"No Found") -> TDAR013 | B21: M. Irfan K | C21: PythonDjango-React | D21: =COUNTIF($B$3:B41,B21) -> 1 | E21: 46182 | F21: 4 | G21: =IF(F21="","Pending",IF(F21<7,"Weekback","No Weekback")) -> Weekback
A22: =_xlfn.XLOOKUP(B22,'All '!B:B,'All '!A:A,"No Found") -> TDAR014 | B22: Nihal Roshan | C22: PythonDjango-React | D22: =COUNTIF($B$3:B42,B22) -> 1 | E22: 46182 | F22: 5 | G22: =IF(F22="","Pending",IF(F22<7,"Weekback","No Weekback")) -> Weekback
A23: =_xlfn.XLOOKUP(B23,'All '!B:B,'All '!A:A,"No Found") -> TDAR015 | B23: Fadhil | C23: PythonDjango-React | D23: =COUNTIF($B$3:B43,B23) -> 1 | E23: 46182 | F23: Resheduled | G23: =IF(F23="","Pending",IF(F23<7,"Weekback","No Weekback")) -> No Weekback
A24: =_xlfn.XLOOKUP(B24,'All '!B:B,'All '!A:A,"No Found") -> TDAR016 | B24: Abdul Sabith SB | C24: PythonDjango-React | D24: =COUNTIF($B$3:B44,B24) -> 1 | E24: 46182 | F24: 3.5 | G24: =IF(F24="","Pending",IF(F24<7,"Weekback","No Weekback")) -> Weekback
A25: =_xlfn.XLOOKUP(B25,'All '!B:B,'All '!A:A,"No Found") -> TDAR017 | B25: Abu Hashim | C25: PythonDjango-React | D25: =COUNTIF($B$3:B45,B25) -> 1 | E25: 46182 | F25: 0.5 | G25: =IF(F25="","Pending",IF(F25<7,"Weekback","No Weekback")) -> Weekback
A26: =_xlfn.XLOOKUP(B26,'All '!B:B,'All '!A:A,"No Found") -> TDAR018 | B26: Nabla Paleri | C26: PythonDjango-React | D26: =COUNTIF($B$3:B46,B26) -> 1 | E26: 46182 | F26: 5 | G26: =IF(F26="","Pending",IF(F26<7,"Weekback","No Weekback")) -> Weekback
A27: =_xlfn.XLOOKUP(B27,'All '!B:B,'All '!A:A,"No Found") -> TDAR019 | B27: Fidha Jebin | C27: PythonDjango-React | D27: =COUNTIF($B$3:B47,B27) -> 1 | E27: 46182 | F27: 7.5 | G27: =IF(F27="","Pending",IF(F27<7,"Weekback","No Weekback")) -> No Weekback
A28: =_xlfn.XLOOKUP(B28,'All '!B:B,'All '!A:A,"No Found") -> TDAR020 | B28: Jabir Ali | C28: PythonDjango-React | D28: =COUNTIF($B$3:B48,B28) -> 1 | E28: 46182 | F28: 4 | G28: =IF(F28="","Pending",IF(F28<7,"Weekback","No Weekback")) -> Weekback
A29: =_xlfn.XLOOKUP(B29,'All '!B:B,'All '!A:A,"No Found") -> TDAR021 | B29: Shiyas Ahmad | C29: PythonDjango-React | D29: =COUNTIF($B$3:B49,B29) -> 1 | E29: 46182 | F29: 5 | G29: =IF(F29="","Pending",IF(F29<7,"Weekback","No Weekback")) -> Weekback
A30: =_xlfn.XLOOKUP(B30,'All '!B:B,'All '!A:A,"No Found") -> TDAA003 | B30: Nidhal Muhammad PC | C30: PythonDjango-Angular | D30: =COUNTIF($B$3:B50,B30) -> 1 | E30: 46182 | F30: 4 | G30: =IF(F30="","Pending",IF(F30<7,"Weekback","No Weekback")) -> Weekback
A31: =_xlfn.XLOOKUP(B31,'All '!B:B,'All '!A:A,"No Found") -> TDAF002 | B31: Muhammed Shahid | C31: Python Flutter | D31: =COUNTIF($B$3:B51,B31) -> 1 | E31: 46182 | F31: 7 | G31: =IF(F31="","Pending",IF(F31<7,"Weekback","No Weekback")) -> No Weekback
A32: =_xlfn.XLOOKUP(B32,'All '!B:B,'All '!A:A,"No Found") -> TDAF003 | B32: Hudha Reema | C32: Python Flutter | D32: =COUNTIF($B$3:B52,B32) -> 1 | E32: 46182 | F32: 7.5 | G32: =IF(F32="","Pending",IF(F32<7,"Weekback","No Weekback")) -> No Weekback
A33: =_xlfn.XLOOKUP(B33,'All '!B:B,'All '!A:A,"No Found") -> TDAR022 | B33: Jithin | C33: PythonDjango-React | D33: =COUNTIF($B$3:B53,B33) -> 1 | E33: 46182 | F33: 7 | G33: =IF(F33="","Pending",IF(F33<7,"Weekback","No Weekback")) -> No Weekback
A34: =_xlfn.XLOOKUP(B34,'All '!B:B,'All '!A:A,"No Found") -> TDAU005 | B34: Sinan | C34: UX-React | D34: 1 | E34: 46191 | F34: 3 | G34: =IF(F34="","Pending",IF(F34<7,"Weekback","No Weekback")) -> Weekback
A35: =_xlfn.XLOOKUP(B35,'All '!B:B,'All '!A:A,"No Found") -> TDAR001 | B35: M Shameel | C35: PythonDjango-React | D35: 1 | E35: 46191 | F35: 8 | G35: =IF(F35="","Pending",IF(F35<7,"Weekback","No Weekback")) -> No Weekback
A36: =_xlfn.XLOOKUP(B36,'All '!B:B,'All '!A:A,"No Found") -> TDAR008 | B36: Sajeer Fasil | C36: PythonDjango-React | D36: 1 | E36: 46191 | F36: 5 | G36: =IF(F36="","Pending",IF(F36<7,"Weekback","No Weekback")) -> Weekback
A37: =_xlfn.XLOOKUP(B37,'All '!B:B,'All '!A:A,"No Found") -> TDAA002 | B37: Ameera K | C37: PythonDjango-Angular | D37: 1 | E37: 46191 | F37: 5.5 | G37: =IF(F37="","Pending",IF(F37<7,"Weekback","No Weekback")) -> Weekback
A38: =_xlfn.XLOOKUP(B38,'All '!B:B,'All '!A:A,"No Found") -> TDAM009 | B38: Abinav | C38: MERN | D38: 1 | E38: 46191 | F38: 5 | G38: =IF(F38="","Pending",IF(F38<7,"Weekback","No Weekback")) -> Weekback
A39: =_xlfn.XLOOKUP(B39,'All '!B:B,'All '!A:A,"No Found") -> TDAN001 | B39: M. Shabeeb | C39: Python Next js | D39: 1 | E39: 46191 | F39: 7 | G39: =IF(F39="","Pending",IF(F39<7,"Weekback","No Weekback")) -> No Weekback
A40: =_xlfn.XLOOKUP(B40,'All '!B:B,'All '!A:A,"No Found") -> TDAM008 | B40: Aswin kc | C40: =_xlfn.XLOOKUP($B40,'All '!B:B,'All '!C:C,"No Found") -> MERN | D40: 1 | E40: 46206 | F40: 8 | G40: =IF(F40="","Pending",IF(F40<7,"Weekback","No Weekback")) -> No Weekback
...

Sheet Dashboard.
F5: Nidhal Muhammad PC
F7: STD ID : | H7: =_xlfn.XLOOKUP(F5,'All '!B:B,'All '!A:A,"Not Available") -> TDAA003
C10: COURSE PROGRESS | K10: STUDENT REVIEW
C11: Course Name | F11: =_xlfn.XLOOKUP(F5,'All '!B:B,'All '!C:C,"Not Available") -> PythonDjango-Angular | K11: Course | N11: =_xlfn.XLOOKUP(F5,'All '!B:B,'All '!C:C,"Not Available") -> PythonDjango-Angular
C12: Current Topic | F12: =_xlfn.XLOOKUP(F5,'All '!B:B,'All '!D:D,"Not Available") -> Python | K12: Review no | N12: 1
C13: Progress | F13: =_xlfn.XLOOKUP(F5,'All '!B:B,'All '!E:E,"Not Available") -> file handling | K13: Date reviewed | N13: {=_xlfn.XLOOKUP(1,('Review History'!B:B=Dashboard.!F5)*('Review History'!D:D=Dashboard.!N12),'Review History'!E:E,"Not Available")} -> 46182
C14: Staff Name | F14: =_xlfn.XLOOKUP(F5,'All '!B:B,'All '!H:H,"Not Available") -> Jan Sabith | K14: Mark | N14: {=_xlfn.XLOOKUP(1,('Review History'!B:B=Dashboard.!F5)*('Review History'!D:D=Dashboard.!N12)*('Review History'!E:E=Dashboard.!N13),'Review History'!F:F,"Not Available")} -> 4
C15: Beginning Date | F15: =IF(_xlfn.XLOOKUP(F5,'All '!B:B,'All '!F:F,"")="","Not Available",_xlfn.XLOOKUP(#REF!,'All '!B:B,'All '!F:F,"")) -> Not Available | K15: Status | N15: =IF(N14<7,"Weekback","No Weekback") -> Weekback
C16: End Date | F16: =_xlfn.XLOOKUP(F5,'All '!B:B,'All '!G:G,"Not Available") -> 46337 | K16: Trainer | N16: =IF(_xlfn.XLOOKUP(F5,'Review History'!B:B,'Review History'!H:H,"Not Available")="","Not Available") -> Not Available
C18: ATTENDANCE | K18: PRESENTATION
C19: Current Date | F19: 46213 | K19: Presentation no | N19: ='Presentation History'!M9 -> 1
C20: Status | F20: =IFERROR(INDEX('Staff - Student'!E2:V1007,MATCH(F5,'Staff - Student'!C2:C1007,0),MATCH(F19,'Staff - Student'!E1:DK1,0)),"Not Marked") -> Not Marked | K20: Topic | N20: {=_xlfn.XLOOKUP(1,('Presentation History'!B:B=Dashboard.!F5)*('Presentation History'!F:F=Dashboard.!N19),'Presentation History'!C:C,"Not Found")} -> Web3
C21: Total Days | F21: =SUM(F22:I23) -> 28.5
C22: Working Days | F22: =_xlfn.XLOOKUP(F5,'Staff - Student'!C:C,'Staff - Student'!JF:JF,"Not Available") -> 25.5 | K22: Date | N22: {=_xlfn.LET( _xlpm.d,_xlfn.XLOOKUP( 1, ('Presentation History'!B:B=F5)*('Presentation History'!F:F=N19), 'Presentation History'!D:D, "Not Available" ), IF(OR(_xlpm.d="",_xlpm.d="Not Available"),"Not Available",_xlpm.d))} -> 46211
C23: Absent Days | F23: =_xlfn.XLOOKUP(F5,'Staff - Student'!C:C,'Staff - Student'!JG:JG,"Not Available") -> 3 | K23: Status | N23: {=IF(_xlfn.XLOOKUP(1,('Presentation History'!B:B=Dashboard.!F5)*('Presentation History'!F:F=Dashboard.!N19)*('Presentation History'!C:C=Dashboard.!N20),'Presentation History'!E:E)="Done","Done","Not Done")} -> Done

Sheet Staff - Student
A1: SI No | B1: Staff | C1: Name | D1: Course | E1: 6-Jul | F1: 7-Jul | G1: 8-Jul | H1: 9-Jul | I1: 10-Jul | J1: 13-Jul | K1: 14-Jul | L1: 15-Jul | M1: 16-Jul | N1: 17-Jul | O1: 20-Jul | P1: 21-Jul | Q1: 22-Jul | R1: 23-Jul | S1: 24-Jul | T1: 27-Jul | U1: 28-Jul | V1: 29-Jul | W1: 30-Jul | X1: 31-Jul | Y1: 3-Aug | Z1: 4-Aug | AA1: 5-Aug | AB1: 6-Aug | AC1: 7-Aug | AD1: 10-Aug | AE1: 11-Aug | AF1: 12-Aug | AG1: 13-Aug | AH1: 14-Aug | AI1: 17-Aug | AJ1: 18-Aug | AK1: 19-Aug | AL1: 20-Aug | AM1: 21-Aug | AN1: 24-Aug | AO1: 25-Aug | AP1: 31-Aug | AQ1: 1-Sep | AR1: 2-Sep | AS1: 3-Sep | AT1: 4-Sep | AU1: 5-Sep | AV1: 6-Sep | AW1: 7-Sep | AX1: 8-Sep | AY1: 9-Sep | AZ1: 10-Sep | BA1: 11-Sep | BB1: 12-Sep | BC1: 13-Sep | BD1: 14-Sep | BE1: 15-Sep | BF1: 16-Sep | BG1: 17-Sep | BH1: 18-Sep | BI1: 19-Sep | BJ1: 20-Sep | BK1: 21-Sep | BL1: 22-Sep | BM1: 23-Sep | BN1: 24-Sep | BO1: 25-Sep | BP1: 26-Sep | BQ1: 27-Sep | BR1: 28-Sep | BS1: 29-Sep | BT1: 30-Sep | BU1: 1-Oct | BV1: 2-Oct | BW1: 3-Oct | BX1: 4-Oct | BY1: 5-Oct | BZ1: 6-Oct | CA1: 7-Oct | CB1: 8-Oct | CC1: 9-Oct | CD1: 10-Oct | CE1: 11-Oct | CF1: 12-Oct | CG1: 13-Oct | CH1: 14-Oct | CI1: 15-Oct | CJ1: 16-Oct | CK1: 17-Oct | CL1: 18-Oct | CM1: 19-Oct | CN1: 20-Oct | CO1: 21-Oct | CP1: 22-Oct | CQ1: 23-Oct | CR1: 24-Oct | CS1: 25-Oct | CT1: 26-Oct | CU1: 27-Oct | CV1: 28-Oct | CW1: 29-Oct | CX1: 30-Oct | CY1: 31-Oct | CZ1: 1-Nov | DA1: 2-Nov | DB1: 3-Nov | DC1: 4-Nov | JF1: Working Days | JG1: Absent
A2: 1 | B2: Saheer | C2: Fathima Rafa | D2: UI UX React | E2: Present | F2: Absent | G2: Present | H2: Absent | I2: Present | J2: Present | K2: Absent | L2: Absent | M2: Present | N2: Absent | O2: Absent | P2: Absent | Q2: Absent | R2: Absent | S2: Absent | T2: Absent | U2: Absent | V2: Absent | W2: Absent | X2: Absent | Y2: Absent | Z2: Absent | AA2: Absent | AB2: Present | AC2: Present | AD2: Present | AE2: Absent | AF2: Absent | AG2: Absent | JF2: =COUNTIF(E2:DK2,"Present")+(COUNTIF(E2:DK2,"Half Day")*0.5) -> 8 | JG2: =COUNTIF($E2:$DK2,"Absent")+(COUNTIF($E2:$DK2,"P(Half Day)")*0.5) -> 21 | JI2: =COUNTIF($E2:$JE2,"Present")+(COUNTIF($E2:$JE2,"Half Day")*0.5) -> 8
A3: 2 | C3: Faheem | D3: UI UX React | E3: Absent | F3: Absent | G3: Present | H3: Present | I3: Present | J3: Present | K3: Present | L3: Present | M3: Absent | N3: Absent | O3: Absent | P3: Present | Q3: Absent | R3: Absent | S3: Absent | T3: Present | U3: Absent | V3: Present | W3: Present | X3: Present | Y3: Absent | Z3: Present | AA3: Present | AB3: Present | AC3: Present | AD3: Present | AE3: Present | AF3: Absent | AG3: Absent | JF3: =COUNTIF(E3:DK3,"Present")+(COUNTIF(E3:DK3,"Half Day")*0.5) -> 17 | JG3: =COUNTIF($E3:$DK3,"Absent")+(COUNTIF($E3:$DK3,"P(Half Day)")*0.5) -> 12
A4: 3 | C4: Fathima Safna | D4: UI UX React | E4: Present | F4: Present | G4: Present | H4: Absent | I4: Present | J4: Present | K4: Present | L4: Present | M4: Present | N4: Absent | O4: Absent | P4: Present | Q4: Absent | R4: Present | S4: Present | T4: Present | U4: Present | V4: Present | W4: Present | X4: Present | Y4: Absent | Z4: Absent | AA4: Present | AB4: Present | AC4: Present | AD4: Present | AE4: Absent | AF4: Absent | AG4: Present | JF4: =COUNTIF(E4:DK4,"Present")+(COUNTIF(E4:DK4,"Half Day")*0.5) -> 21 | JG4: =COUNTIF($E4:$DK4,"Absent")+(COUNTIF($E4:$DK4,"P(Half Day)")*0.5) -> 8
A5: 4 | C5: Irfan PC | D5: UI UX React | E5: Present | F5: Present | G5: Present | H5: Present | I5: Present | J5: Present | K5: Present | L5: Present | M5: Present | N5: Present | O5: Absent | P5: Present | Q5: Present | R5: Present | S5: Present | T5: Present | U5: Present | V5: Present | W5: Present | X5: Present | Y5: Present | Z5: Present | AA5: Present | AB5: Present | AC5: Present | AD5: Present | AE5: Present | AF5: Present | AG5: Present | JF5: =COUNTIF(E5:DK5,"Present")+(COUNTIF(E5:DK5,"Half Day")*0.5) -> 28 | JG5: =COUNTIF($E5:$DK5,"Absent")+(COUNTIF($E5:$DK5,"P(Half Day)")*0.5) -> 1
A6: 5 | C6: Sinan | D6: UI UX React | E6: Absent | F6: Present | G6: Absent | H6: Absent | I6: Present | J6: Present | K6: Present | L6: Absent | M6: Present | N6: Present | O6: Absent | P6: Absent | Q6: Present | R6: Present | S6: Absent | T6: Present | U6: Present | V6: Present | W6: Present | X6: Absent | Y6: Absent | Z6: Present | AA6: Present | AB6: Present | AC6: Present | AD6: Present | AE6: Absent | AF6: Present | AG6: Present | JF6: =COUNTIF(E6:DK6,"Present")+(COUNTIF(E6:DK6,"Half Day")*0.5) -> 19 | JG6: =COUNTIF($E6:$DK6,"Absent")+(COUNTIF($E6:$DK6,"P(Half Day)")*0.5) -> 10
A7: 6 | C7: Rahsha | D7: UI UX React | E7: Absent | F7: Present | G7: Absent | H7: Absent | I7: Present | J7: Present | K7: Present | L7: Absent | M7: Absent | N7: Absent | O7: Absent | P7: Absent | Q7: Present | R7: Present | S7: Present | T7: Present | U7: Present | V7: Absent | W7: Present | X7: Absent | Y7: Absent | Z7: Absent | AA7: Absent | AB7: Present | AC7: Absent | AD7: Present | AE7: Present | AF7: Half Day | AG7: Half Day | JF7: =COUNTIF(E7:DK7,"Present")+(COUNTIF(E7:DK7,"Half Day")*0.5) -> 14 | JG7: =COUNTIF($E7:$DK7,"Absent")+(COUNTIF($E7:$DK7,"P(Half Day)")*0.5) -> 14
A8: 7 | C8: fathima Hudha | D8: UI UX | E8: Present | F8: Present | G8: Present | H8: Present | I8: Present | J8: Present | K8: Present | L8: Present | M8: Present | N8: Present | O8: Present | P8: Present | Q8: Present | R8: Present | S8: Present | T8: Present | U8: Present | V8: Present | W8: Present | X8: Present | Y8: Absent | Z8: Present | AA8: Present | AB8: Present | AC8: Present | AD8: Present | AE8: Absent | AF8: Present | AG8: Present | JF8: =COUNTIF(E8:DK8,"Present")+(COUNTIF(E8:DK8,"Half Day")*0.5) -> 27 | JG8: =COUNTIF($E8:$DK8,"Absent")+(COUNTIF($E8:$DK8,"P(Half Day)")*0.5) -> 2
A9: 8 | C9: Fathima Juba | D9: UI UX | E9: Present | F9: Present | G9: Present | H9: Present | I9: Present | J9: Present | K9: Present | L9: Present | M9: Present | N9: Present | O9: Present | P9: Present | Q9: Present | R9: Present | S9: Present | T9: Present | U9: Present | V9: Present | W9: Present | X9: Present | Y9: Absent | Z9: Present | AA9: Present | AB9: Present | AC9: Present | AD9: Present | AE9: Absent | AF9: Present | AG9: Present | JF9: =COUNTIF(E9:DK9,"Present")+(COUNTIF(E9:DK9,"Half Day")*0.5) -> 27 | JG9: =COUNTIF($E9:$DK9,"Absent")+(COUNTIF($E9:$DK9,"P(Half Day)")*0.5) -> 2
A10: 9 | C10: Risva Mehafin | D10: UI UX React | JF10: =COUNTIF(E10:DK10,"Present")+(COUNTIF(E10:DK10,"Half Day")*0.5) -> 0 | JG10: =COUNTIF($E10:$DK10,"Absent")+(COUNTIF($E10:$DK10,"P(Half Day)")*0.5) -> 0
A11: 10 | B11: Ameer | C11: Rahees PK | D11: MERN | E11: Absent | F11: Absent | G11: Absent | H11: Absent | I11: Absent | J11: Absent | K11: Absent | L11: Absent | M11: Absent | N11: Absent | O11: Absent | P11: Absent | Q11: Absent | R11: Absent | S11: Absent | T11: Absent | U11: Absent | V11: Absent | W11: Absent | X11: Absent | Y11: Absent | Z11: Absent | AA11: Absent | AB11: Absent | AC11: Absent | AD11: Absent | AE11: Absent | AF11: Absent | AG11: Absent | AH11: Absent | AI11: Absent | AJ11: Absent | JF11: =COUNTIF(E11:DK11,"Present")+(COUNTIF(E11:DK11,"Half Day")*0.5) -> 0 | JG11: =COUNTIF($E11:$DK11,"Absent")+(COUNTIF($E11:$DK11,"P(Half Day)")*0.5) -> 32
A12: 11 | C12: Nibrasul Haqu C | D12: MERN | E12: Present | F12: Present | G12: Absent | H12: Absent | I12: Absent | J12: Present | K12: Present | L12: Present | M12: Present | N12: Present | O12: Absent | P12: Absent | Q12: Present | R12: Present | S12: Present | T12: Absent | U12: Present | V12: Present | W12: Present | X12: Present | Y12: Absent | Z12: Absent | AA12: Present | AB12: Present | AC12: Present | AD12: Present | AE12: Present | AF12: Present | AG12: Present | AH12: Present | AI12: Absent | AJ12: Present | JF12: =COUNTIF(E12:DK12,"Present")+(COUNTIF(E12:DK12,"Half Day")*0.5) -> 23 | JG12: =COUNTIF($E12:$DK12,"Absent")+(COUNTIF($E12:$DK12,"P(Half Day)")*0.5) -> 9
A13: 12 | C13: Harshal | D13: MERN | E13: Present | F13: Present | G13: Absent | H13: Absent | I13: Present | J13: Present | K13: Present | L13: Absent | M13: Absent | N13: Present | O13: Absent | P13: Present | Q13: Present | R13: Present | S13: Absent | T13: Absent | U13: Present | V13: Present | W13: Present | X13: Absent | Y13: Absent | Z13: Absent | AA13: Present | AB13: Present | AC13: Present | AD13: Present | AE13: Absent | AF13: Present | AG13: Present | AH13: Absent | AI13: Present | AJ13: Present | JF13: =COUNTIF(E13:DK13,"Present")+(COUNTIF(E13:DK13,"Half Day")*0.5) -> 20 | JG13: =COUNTIF($E13:$DK13,"Absent")+(COUNTIF($E13:$DK13,"P(Half Day)")*0.5) -> 12
A14: 13 | C14: Aswin KC | D14: MERN | E14: Present | F14: Present | G14: Present | H14: Present | I14: Present | J14: Present | K14: Present | L14: Present | M14: Present | N14: Present | O14: Present | P14: Present | Q14: Present | R14: Present | S14: Present | T14: Present | U14: Present | V14: Present | W14: Present | X14: Present | Y14: Present | Z14: Present | AA14: Present | AB14: Present | AC14: Present | AD14: Present | AE14: Present | AF14: Present | AG14: Present | AH14: Present | AI14: Present | AJ14: Present | JF14: =COUNTIF(E14:DK14,"Present")+(COUNTIF(E14:DK14,"Half Day")*0.5) -> 32 | JG14: =COUNTIF($E14:$DK14,"Absent")+(COUNTIF($E14:$DK14,"P(Half Day)")*0.5) -> 0
A15: 14 | C15: Abinav | D15: MERN | E15: Present | F15: Present | G15: Present | H15: Present | I15: Present | J15: Present | K15: Present | L15: Present | M15: Present | N15: Present | O15: Absent | P15: Present | Q15: Present | R15: Present | S15: Present | T15: Present | U15: Present | V15: Present | W15: Present | X15: Present | Y15: Present | Z15: Present | AA15: Present | AB15: Present | AC15: Present | AD15: Present | AE15: Present | AF15: Present | AG15: Present | AH15: Present | AI15: Present | AJ15: Present | JF15: =COUNTIF(E15:DK15,"Present")+(COUNTIF(E15:DK15,"Half Day")*0.5) -> 31 | JG15: =COUNTIF($E15:$DK15,"Absent")+(COUNTIF($E15:$DK15,"P(Half Day)")*0.5) -> 1
A16: 15 | C16: Ajmal | D16: Python Angular | E16: Absent | F16: Present | G16: Absent | H16: Present | I16: Present | J16: Present | K16: Present | L16: Present | M16: Present | N16: Present | O16: Absent | P16: Present | Q16: Present | R16: Present | S16: Absent | T16: Absent | U16: Present | V16: Present | W16: Present | X16: Present | Y16: Present | Z16: Present | AA16: Present | AB16: Present | AC16: Present | AD16: Present | AE16: Present | AF16: Present | AG16: Present | AH16: Absent | AI16: Absent | AJ16: Present | JF16: =COUNTIF(E16:DK16,"Present")+(COUNTIF(E16:DK16,"Half Day")*0.5) -> 25 | JG16: =COUNTIF($E16:$DK16,"Absent")+(COUNTIF($E16:$DK16,"P(Half Day)")*0.5) -> 7
A17: 16 | C17: M. Safeer | D17: MERN | E17: Present | F17: Present | G17: Present | H17: Present | I17: Present | J17: Present | K17: Present | L17: Present | M17: Present | N17: Present | O17: Absent | P17: Absent | Q17: Absent | R17: Present | S17: Present | T17: Present | U17: Present | V17: Present | W17: Present | X17: Present | Y17: Absent | Z17: Present | AA17: Present | AB17: Present | AC17: Present | AD17: Absent | AE17: Present | AF17: Present | AG17: Present | AH17: Absent | AI17: Present | AJ17: Absent | JF17: =COUNTIF(E17:DK17,"Present")+(COUNTIF(E17:DK17,"Half Day")*0.5) -> 25 | JG17: =COUNTIF($E17:$DK17,"Absent")+(COUNTIF($E17:$DK17,"P(Half Day)")*0.5) -> 7
A18: 17 | C18: M. Danish | D18: MERN | E18: Half Day | F18: Absent | G18: Present | H18: Half Day | I18: Absent | J18: Absent | K18: Present | L18: Present | M18: Absent | N18: Absent | O18: Absent | P18: Absent | Q18: Absent | R18: Present | S18: Absent | T18: Present | U18: Present | V18: Present | W18: Absent | X18: Absent | Y18: Absent | Z18: Absent | AA18: Present | AB18: Present | AC18: Absent | AD18: Absent | AE18: Half Day | AF18: Present | AG18: Absent | AH18: Absent | AI18: Absent | AJ18: Absent | JF18: =COUNTIF(E18:DK18,"Present")+(COUNTIF(E18:DK18,"Half Day")*0.5) -> 11.5 | JG18: =COUNTIF($E18:$DK18,"Absent")+(COUNTIF($E18:$DK18,"P(Half Day)")*0.5) -> 19
A19: 18 | C19: Hisham | D19: MERN | E19: Absent | F19: Absent | G19: Present | H19: Absent | I19: Present | J19: Present | K19: Present | L19: Present | M19: Absent | N19: Present | O19: Absent | P19: Present | Q19: Absent | R19: Present | S19: Absent | T19: Absent | U19: Present | V19: Present | W19: Present | X19: Present | Y19: Absent | Z19: Present | AA19: Present | AB19: Present | AC19: Present | AD19: Present | AE19: Absent | AF19: Absent | AG19: Present | AH19: Absent | AI19: Present | AJ19: Present | JF19: =COUNTIF(E19:DK19,"Present")+(COUNTIF(E19:DK19,"Half Day")*0.5) -> 20 | JG19: =COUNTIF($E19:$DK19,"Absent")+(COUNTIF($E19:$DK19,"P(Half Day)")*0.5) -> 12
C20: Jumana | D20: MERN | Y20: Present | Z20: Present | AA20: Present | AB20: Present | AC20: Present | AD20: Absent | AE20: Present | AF20: Present | AG20: Present | AH20: Present | AI20: Present | AJ20: Present
C21: M. Azad | D21: MERN | Y21: Present | Z21: Present | AA21: Present | AB21: Present | AC21: Present | AD21: Present | AE21: Present | AF21: Present | AG21: Present | AH21: Present | AI21: Present | AJ21: Present
C22: M Shameem | D22: MERN | Y22: Present | Z22: Present | AA22: Present | AB22: Present | AC22: Present | AD22: Present | AE22: Present | AF22: Present | AG22: Present | AH22: Present | AI22: Present | AJ22: Present
A23: 19 | B23: Anandu | C23: M. Irfan K | D23: Python React | E23: Present | F23: Present | G23: Present | H23: Present | I23: Absent | J23: Present | K23: Present | L23: Present | M23: Present | N23: Present | O23: Absent | P23: Absent | Q23: Absent | R23: Present | S23: Present | T23: Present | U23: Present | V23: Present | W23: Present | X23: Absent | Y23: Absent | Z23: Absent | AA23: Absent | JF23: =COUNTIF(E23:DK23,"Present")+(COUNTIF(E23:DK23,"Half Day")*0.5) -> 15 | JG23: =COUNTIF($E23:$DK23,"Absent")+(COUNTIF($E23:$DK23,"P(Half Day)")*0.5) -> 8
A24: 20 | C24: M. Ajmal CP | D24: Python React | E24: Absent | F24: Absent | G24: Absent | H24: Absent | I24: Absent | J24: Present | K24: Present | L24: Present | M24: Present | N24: Half Day | O24: Absent | P24: Absent | Q24: Present | R24: Present | S24: Present | T24: Present | U24: Present | V24: Present | W24: Absent | X24: Absent | Y24: Absent | Z24: Absent | AA24: Present | JF24: =COUNTIF(E24:DK24,"Present")+(COUNTIF(E24:DK24,"Half Day")*0.5) -> 11.5 | JG24: =COUNTIF($E24:$DK24,"Absent")+(COUNTIF($E24:$DK24,"P(Half Day)")*0.5) -> 11
A25: 21 | C25: M. Rameesh KP | D25: Python React | E25: Absent | F25: Absent | G25: Present | H25: Present | I25: Present | J25: Present | K25: Present | L25: Present | M25: Absent | N25: Absent | O25: Present | P25: Present | Q25: Present | R25: Present | S25: Absent | T25: Present | U25: Present | V25: Half Day | W25: Half Day | X25: Half Day | Y25: Present | Z25: Present | AA25: Present | JF25: =COUNTIF(E25:DK25,"Present")+(COUNTIF(E25:DK25,"Half Day")*0.5) -> 16.5 | JG25: =COUNTIF($E25:$DK25,"Absent")+(COUNTIF($E25:$DK25,"P(Half Day)")*0.5) -> 5
A26: 22 | C26: M. Irfan H | D26: Python React | E26: Present | F26: Absent | G26: Present | H26: Present | I26: Present | J26: Present | K26: Present | L26: Present | M26: Absent | N26: Present | O26: Present | P26: Present | Q26: Present | R26: Present | S26: Absent | T26: Present | U26: Present | V26: Half Day | W26: Half Day | X26: Half Day | Y26: Present | Z26: Present | AA26: Present | JF26: =COUNTIF(E26:DK26,"Present")+(COUNTIF(E26:DK26,"Half Day")*0.5) -> 18.5 | JG26: =COUNTIF($E26:$DK26,"Absent")+(COUNTIF($E26:$DK26,"P(Half Day)")*0.5) -> 3
A27: 23 | C27: Abu Hashim | D27: Python React | E27: Absent | F27: Absent | G27: Absent | H27: Absent | I27: Absent | J27: Absent | K27: Absent | L27: Absent | M27: Absent | N27: Absent | O27: Absent | P27: Absent | Q27: Absent | R27: Absent | S27: Absent | T27: Absent | U27: Absent | V27: Absent | W27: Absent | X27: Absent | Y27: Absent | Z27: Absent | AA27: Absent | JF27: =COUNTIF(E27:DK27,"Present")+(COUNTIF(E27:DK27,"Half Day")*0.5) -> 0 | JG27: =COUNTIF($E27:$DK27,"Absent")+(COUNTIF($E27:$DK27,"P(Half Day)")*0.5) -> 23
A28: 24 | C28: Nihal Roshan | D28: Python React | E28: Half Day | F28: Half Day | G28: Absent | H28: Absent | I28: Absent | J28: Absent | K28: Absent | L28: Present | M28: Present | N28: Present | O28: Absent | P28: Absent | Q28: Absent | R28: Present | S28: Absent | T28: Present | U28: Present | V28: Present | W28: Present | X28: Absent | Y28: Absent | Z28: Present | AA28: Present | JF28: =COUNTIF(E28:DK28,"Present")+(COUNTIF(E28:DK28,"Half Day")*0.5) -> 11 | JG28: =COUNTIF($E28:$DK28,"Absent")+(COUNTIF($E28:$DK28,"P(Half Day)")*0.5) -> 11
A29: 25 | B29: Vishnu | C29: Abdul Sabith SB | D29: Python React | E29: Half Day | F29: Half Day | G29: Absent | H29: Absent | I29: Absent | J29: Absent | K29: Half Day | L29: Absent | M29: Half Day | N29: Present | O29: Absent | P29: Absent | Q29: Absent | R29: Absent | S29: Absent | T29: Present | U29: Present | V29: Absent | W29: Absent | X29: Present | Y29: Absent | Z29: Absent | AA29: Absent | AB29: Absent | AC29: Absent | AD29: Absent | JF29: =COUNTIF(E29:DK29,"Present")+(COUNTIF(E29:DK29,"Half Day")*0.5) -> 6 | JG29: =COUNTIF($E29:$DK29,"Absent")+(COUNTIF($E29:$DK29,"P(Half Day)")*0.5) -> 18
A30: 26 | C30: Jabir Ali | D30: Python React | E30: Absent | F30: Absent | G30: Absent | H30: Absent | I30: Absent | J30: Present | K30: Present | L30: Absent | M30: Absent | N30: Absent | O30: Absent | P30: Absent | Q30: Absent | R30: Present | S30: Present | T30: Absent | U30: Absent | V30: Absent | W30: Absent | X30: Absent | Y30: Absent | Z30: Absent | AA30: Present | AB30: Present | AC30: Present | AD30: Present | JF30: =COUNTIF(E30:DK30,"Present")+(COUNTIF(E30:DK30,"Half Day")*0.5) -> 8 | JG30: =COUNTIF($E30:$DK30,"Absent")+(COUNTIF($E30:$DK30,"P(Half Day)")*0.5) -> 18
A31: 27 | C31: M. Jamshid | D31: Python React | E31: Present | F31: Half Day | G31: Absent | H31: Absent | I31: Absent | J31: Absent | K31: Half Day | L31: Half Day | M31: Present | N31: Present | O31: Present | P31: Present | Q31: Absent | R31: Absent | S31: Absent | T31: Absent | U31: Present | V31: Absent | W31: Absent | X31: Absent | Y31: Present | Z31: Present | AA31: Present | AB31: Absent | AC31: Absent | AD31: Absent | JF31: =COUNTIF(E31:DK31,"Present")+(COUNTIF(E31:DK31,"Half Day")*0.5) -> 10.5 | JG31: =COUNTIF($E31:$DK31,"Absent")+(COUNTIF($E31:$DK31,"P(Half Day)")*0.5) -> 14
A32: 28 | C32: M. Shabeeb | D32: Python Next | E32: Absent | F32: Present | G32: Present | H32: Present | I32: Present | J32: Present | K32: Present | L32: Present | M32: Present | N32: Present | O32: Present | P32: Present | Q32: Present | R32: Present | S32: Present | T32: Present | U32: Present | V32: Present | W32: Absent | X32: Present | Y32: Present | Z32: Present | AA32: Present | AB32: Present | AC32: Present | AD32: Present | JF32: =COUNTIF(E32:DK32,"Present")+(COUNTIF(E32:DK32,"Half Day")*0.5) -> 24 | JG32: =COUNTIF($E32:$DK32,"Absent")+(COUNTIF($E32:$DK32,"P(Half Day)")*0.5) -> 2
A33: 29 | C33: M. Muaad | D33: Python React | E33: Present | F33: Present | G33: Present | H33: Present | I33: Present | J33: Present | K33: Present | L33: Present | M33: Present | N33: Present | O33: Present | P33: Present | Q33: Present | R33: Present | S33: Present | T33: Present | U33: Present | V33: Present | W33: Absent | X33: Present | Y33: Present | Z33: Present | AA33: Present | AB33: Present | AC33: Present | AD33: Present | JF33: =COUNTIF(E33:DK33,"Present")+(COUNTIF(E33:DK33,"Half Day")*0.5) -> 25 | JG33: =COUNTIF($E33:$DK33,"Absent")+(COUNTIF($E33:$DK33,"P(Half Day)")*0.5) -> 1
A34: 30 | B34: Aswin PP | C34: Muhammed Rashid T | D34: Python React | E34: Present | F34: Absent | G34: Absent | H34: Present | I34: Absent | J34: Absent | K34: Present | L34: Present | M34: Present | N34: Absent | O34: Absent | P34: Absent | Q34: Absent | R34: Absent | S34: Absent | T34: Absent | U34: Absent | V34: Absent | W34: Absent | X34: Absent | Y34: Absent | Z34: Absent | AA34: Absent | AB34: Absent | AC34: Absent | AD34: Absent | AE34: Absent | AF34: Absent | JF34: =COUNTIF(E34:DK34,"Present")+(COUNTIF(E34:DK34,"Half Day")*0.5) -> 5 | JG34: =COUNTIF($E34:$DK34,"Absent")+(COUNTIF($E34:$DK34,"P(Half Day)")*0.5) -> 23
A35: 31 | C35: M Shameel | D35: Python React | E35: Absent | F35: Absent | G35: Absent | H35: Present | I35: Half Day | J35: Absent | K35: Absent | L35: Present | M35: Present | N35: Absent | O35: Absent | P35: Absent | Q35: Absent | R35: Absent | S35: Absent | T35: Absent | U35: Absent | V35: Absent | W35: Absent | X35: Absent | Y35: Absent | AA35: Absent | AB35: Present | JF35: =COUNTIF(E35:DK35,"Present")+(COUNTIF(E35:DK35,"Half Day")*0.5) -> 4.5 | JG35: =COUNTIF($E35:$DK35,"Absent")+(COUNTIF($E35:$DK35,"P(Half Day)")*0.5) -> 18
A36: 32 | C36: M. Shamil TK | D36: Python React | E36: Present | F36: Present | G36: Present | H36: Present | I36: Present | J36: Half Day | K36: Present | L36: Absent | M36: Absent | N36: Present | O36: Absent | P36: Present | Q36: Present | R36: Present | S36: Present | T36: Present | U36: Present | V36: Present | W36: Present | X36: Present | Y36: Present | Z36: Present | AA36: Present | AB36: Present | AC36: Present | AD36: Present | AE36: Present | AF36: Present | AG36: Present | JF36: =COUNTIF(E36:DK36,"Present")+(COUNTIF(E36:DK36,"Half Day")*0.5) -> 25.5 | JG36: =COUNTIF($E36:$DK36,"Absent")+(COUNTIF($E36:$DK36,"P(Half Day)")*0.5) -> 3
A37: 33 | C37: Muhammed Unais K | D37: Python React | JF37: =COUNTIF(E37:DK37,"Present")+(COUNTIF(E37:DK37,"Half Day")*0.5) -> 0 | JG37: =COUNTIF($E37:$DK37,"Absent")+(COUNTIF($E37:$DK37,"P(Half Day)")*0.5) -> 0
A38: 34 | C38: Shiyas Ahmad | D38: Python React | E38: Present | F38: Present | G38: Present | H38: Present | I38: Present | J38: Present | K38: Present | L38: Present | M38: Present | N38: Present | O38: Present | P38: Present | Q38: Present | R38: Absent | S38: Absent | T38: Absent | U38: Absent | V38: Absent | W38: Absent | X38: Absent | Y38: Present | Z38: Present | AA38: Present | AB38: Present | AC38: Present | AD38: Absent | AE38: Present | AF38: Present | AG38: Present | JF38: =COUNTIF(E38:DK38,"Present")+(COUNTIF(E38:DK38,"Half Day")*0.5) -> 21 | JG38: =COUNTIF($E38:$DK38,"Absent")+(COUNTIF($E38:$DK38,"P(Half Day)")*0.5) -> 8
C39: Rabeehath V | D39: Python React | O39: Present | P39: Present | Q39: Present | R39: Present | S39: Present | T39: Present | U39: Present | V39: Present | W39: Present | X39: Present | Y39: Present | Z39: Present | AA39: Present | AB39: Present | AC39: Present | AD39: Present | AE39: Absent | AF39: Present | AG39: Present | JF39: =COUNTIF(E39:DK39,"Present")+(COUNTIF(E39:DK39,"Half Day")*0.5) -> 18 | JG39: =COUNTIF($E39:$DK39,"Absent")+(COUNTIF($E39:$DK39,"P(Half Day)")*0.5) -> 1
C40: M. Nihal CP | D40: Python React | AC40: Present | AD40: Present | AE40: Present | AF40: Present | AG40: Present
...

Sheet Current-students
A1: Staff | B1: Name | C1: Course | D1: Email | E1: Phone
A2: Abin Raj | B2: Fidha Jebin | C2: Python React | D2: fidhajebin5099@gmail.com | E2: +91 7510205099
B3: Jinsila | C3: Python Next js | D3: jinujinsila132@gmail.com | E3: +91 7592960624
B4: M Nabhan | C4: PythonDjango-React | D4: nabhannabu768@gmail.com | E4: +91 8891425450
B5: M. Sinan M | C5: Python Next js | D5: muhammedsinan7901@gmail.com | E5: +91 7736979724
B6: Raneed | C6: Python React | D6: Raneedellyas@gmail.com | E6: +91 8891573780
B7: Sajeer Fasil | C7: Python React | D7: fazilfazi2007@gmail.com | E7: +91 8891454600
A8: Ameer | B8: Abinav | C8: MERN | D8: abhinavabhi.7364@gmail.com | E8: +91 9778751070
B9: Ajmal | C9: Python Angular | D9: Ajmalajmal0665@gmail.com | E9: +91 8590966165
B10: Aswin KC | C10: MERN | D10: aswinrajcholakuzhi@gmail.com | E10: +91 7907412065
B11: Harshal | C11: MERN | D11: arshalmuhammed85@gmail.com | E11: +91 9778253529
B12: Hisham | C12: MERN | D12: muhammadhishamklpm@gmail.com | E12: +91 7012208998
B13: Jumana | C13: MERN | D13: sherinjumana298@gmail.com | E13: +91 9207340531
B14: M Shameem | C14: MERN | D14: shameemr894@gmail.com | E14: +91 8943267785
B15: M. Azad | C15: MERN | D15: muhammedazad700@gmail.com | E15: +91 8848862172
B16: M. Danish | C16: MERN | D16: danishlaice@gmail.com | E16: +91 9645849933
B17: M. Safeer | C17: MERN | D17: safeerzaid4@gmail.com | E17: +91 6235283718
B18: Nibrasul Haqu C | C18: MERN | D18: nibraz0000@gmail.com | E18: +91 7025954961
B19: Rahees PK | C19: MERN | D19: raheespkrahees802@gmail.com | E19: +91 8589857496
A20: Anandu | B20: Abu Hashim | C20: Python React
B21: M. Ajmal CP | C21: Python React | E21: +91 8921712671
B22: M. Irfan H | C22: Python React | D22: mirfanh904@gmail.com | E22: +91 9048212982
B23: M. Irfan K | C23: Python React | D23: irfanmuthu56@gmail.com | E23: +91 8086175728
B24: M. Rameesh KP | C24: Python React | D24: rameezmhmd855@gmail.com | E24: +91 9072090250
B25: Nihal Roshan | C25: Python React | D25: nihalroshanv@gmail.com | E25: +91 9645405645
A26: Aswin KP | B26: F. Minha | C26: Python Next js | D26: Fathimaaminhaa473@gmail.com | E26: +91 9947619858
B27: M Nasif | C27: MERN | D27: Nasifnishu115@gamil.com | E27: +91 9746737416
B28: M Sinan | C28: MERN | D28: svk511342@gmail.com | E28: +91 9526218118
B29: Rifana | C29: Python Next js | D29: rifanaavp@gmail.com | E29: +91 9292014016
B30: Safwan | C30: Python | D30: safvanvarappara@gmail.com | E30: +91 9847456344
A31: Aswin PP | B31: Afeef Ahammed VV | C31: Python React | D31: ahmedafeef080@gmail.com | E31: +91 8590721047
B32: M. Nihal CP | C32: Python React | D32: nihalabdulla8131@gmail.com | E32: +91 9495939823
B33: Rabeehath V | C33: Python React | D33: rabeemonu@gmail.com | E33: +91 8891909201
B34: Shiyas Ahmad | C34: Python React | D34: shiyasahmad555@gmail.com | E34: +91 7012587705
A35: Jan Sabith | B35: Ameera K | C35: Python React | D35: aymanami3006@gmail.com | E35: 9061382006
B36: Ashil | C36: Python React | D36: mohamedashilpavuthodika@gmail.com | E36: 8139853040
B37: Danial Darvash | C37: MERN | D37: danialdarvesh71@gmail.com | E37: +91 9946162710
B38: Nabla Paleri | C38: Python React
B39: Nidhal Muhammad PC | C39: Python React | D39: pcnidhal85@gmail.com | E39: 9895393902
B40: Shehin | C40: Python React | D40: shhinmohammedak@gmail.com | E40: 7736319781
...

Sheet NEW Students
A1: SI No | B1: Name | C1: Course Name | D1: Current Topic | E1: Progress | F1: Start | G1: Validity
A2: 1 | B2: Fidha Jebin | C2: PythonDjango-React | D2: Django | E2: REST | F2: 46113 | H2: V/A
A3: 2 | B3: Nidhal Muhammad PC | C3: PythonDjango-Angular | D3: Python | E3: Arguments | F3: 46132
A4: 3 | B4: Shiyas Ahmad | C4: PythonDjango-React | D4: Python | E4: File Handling | F4: 46146
A5: 4 | B5: Hudha Reema | C5: Python flutter | D5: Python | E5: data structure | F5: 46174
A6: 5 | B6: Muhammed Shahid | C6: Python flutter | D6: Python | E6: data structure | F6: 46174
A7: 6 | B7: M Sinan | C7: MERN | D7: JS | E7: Loops | F7: 46180
A8: 7 | B8: M. Shabeeb | C8: Python Next js | D8: Python | E8: Python | F8: 46188
A9: 8 | B9: Aswin KC | C9: MERN | D9: JS | E9: Array | F9: 46202
A10: 9 | B10: Abinav | C10: MERN | D10: JS | E10: Array | F10: 46202
A11: 10 | B11: Safwan | C11: PythonDjango-React | D11: Python | E11: Arguments | F11: 46209
A12: 11 | B12: M Nasif | C12: MERN | D12: JS | E12: Loops | F12: 46209
A13: 12 | B13: Suhail | C13: Python Internship | D13: Python | E13: Python | F13: 46209
A14: 13 | B14: Rifana | C14: Python Next js | D14: C programming | E14: Functions | F14: 46217
... A20: 19 | B20: Fathima Lena | C20: Data Analytics | D20: Python | E20: Operators | F20: 46232
A21: 20 | B21: M. Azad | C21: MERN | D21: C programming | F21: 46237
A22: 21 | B22: M. Shameem | C22: MERN | D22: C programming | F22: 46237
A23: 22 | B23: Afeef Ahmed | C23: Python Next js | D23: C programming | F23: 46237
A24: 23 | B24: M Nihal CP | C24: Python Next js | D24: C programming | F24: 46237
A25: 24 | B25: Jumana Sherin | C25: MERN | D25: HTML | F25: 46237
A26: 25 | B26: Danial Darvash | C26: MERN | D26: C programming | F26: 46245
A27: 26 | B27: Fathima Minha | C27: Python Next js | F27: 46251
A28: 27 | B28: M. Shehin | C28: PythonDjango-React | F28: 46251

Sheet Presentation History
A1: Std ID | B1: Name | C1: Presentation | D1: Date | E1: Status | F1: presentation no
A2: TDAM001 | B2: Ameesha | C2: Virtual Reality and Augmented Reality | F2: 1
A3: TDAM002 | B3: Rahees PK | C3: Robotics and Automation | F3: 1
A4: TDAM003 | B4: Hisham | C4: Cloud Computing and Its Benefits | D4: 46213 | E4: Done | F4: 1
A5: TDAM004 | B5: Harshal | C5: Internet of Things: Smart Devices Around Us | D5: 46216 | F5: 1
A6: TDAM005 | B6: M. Danish | C6: Artificial Intelligence in Healthcare | F6: 1
A7: TDAM006 | B7: M. Safeer | C7: Cybersecurity and Online Safety | D7: 46212 | E7: Done | F7: 1
A8: TDAM007 | B8: Nibrasul Haqu C | C8: Zustand, File Upload | D8: 46210 | E8: Done | F8: 1
A9: TDAM008 | B9: Aswin KC | C9: Blockchain Technology and Cryptocurrency | D9: 46220 | E9: Done | F9: 1 | M9: {=IFERROR(_xlfn._xlws.SORT(_xlfn.UNIQUE(_xlfn._xlws.FILTER(F:F,B:B=Dashboard.!F5))),0)} -> 1
A10: TDAM009 | B10: Abinav | C10: Machine Learning in Daily Life | D10: 46220 | E10: Done | F10: 1
A11: TDAM010 | B11: M Sinan | C11: Ethical Hacking and Penetration Testing | D11: 46220 | E11: Done | F11: 1
A12: TDAP001 | B12: M Nasif | C12: Ethical Hacking and Penetration Testing | D12: 46219 | F12: 1
A13: TDAP002 | B13: Suhail | C13: Role of Technology in Education | F13: 1
A14: TDAF001 | B14: Safwan | C14: Digital Transformation in Business | F14: 1
A15: TDAF002 | B15: Muhammed Shahid | C15: Web Development: Past, Present, and Future | F15: 1
A16: TDAF003 | B16: Hudha Reema | C16: Big Data and Data Analytics | F16: 1
A17: TDAF004 | B17: Muhammed Munaver V P | F17: 1
A18: TDAF005 | B18: M.Shebil | C18: E-Commerce and Online Payment Security | F18: 1
A19: TDAN001 | B19: M. Shabeeb | C19: Zero Trust Model | D19: 46211 | E19: Done | F19: 1
A20: TDAN002 | B20: Rifana | F20: 1
A21: TDAA001 | B21: Ajmal | C21: Artificial Intelligence in Healthcare | F21: 1
A22: TDAA002 | B22: Ameera K | C22: Green Technology and Sustainable IT | F22: 1
A23: TDAA003 | B23: Nidhal Muhammad PC | C23: Web3 | D23: 46211 | E23: Done | F23: 1
A24: TDAR001 | B24: M Shameel | C24: Smart Homes and Home Automation | D24: 46217 | F24: 1
A25: TDAR002 | B25: M. Shamil TK | C25: Drone Technology and Its Applications | F25: 1
A26: TDAR003 | B26: M. Muaad | C26: Cybercrime and How to Prevent It | D26: 46216 | E26: Done | F26: 1
A27: TDAR004 | B27: M. Nihal | C27: Wearable Technology in Daily Life | D27: 46216 | E27: Done | F27: 1
A28: TDAR005 | B28: M. Ajmal CP | C28: Social Media and Its Impact on Society | F28: 1
A29: TDAR006 | B29: M. Rameesh KP | C29: Cloud Storage vs Local Storage | F29: 1
A30: TDAR007 | B30: M. Irfan H | C30: Quantum Computing: The Next Big Revolution | F30: 1
A31: TDAR008 | B31: Sajeer Fasil | C31: Operating Systems: Windows, Linux, and macOS | F31: 1
A32: TDAR009 | B32: Raneed | C32: Internet Safety for Students | F32: 1
A33: TDAR010 | B33: Ashil | C33: Digital Marketing and Technology | D33: 46213 | E33: Done | F33: 1
A34: TDAR011 | B34: Muhammed Rashid T | C34: Technology in Agriculture | F34: 1
A35: TDAR012 | B35: M. Jamshid | C35: Smart Cities and Technology | F35: 1
A36: TDAR013 | B36: M. Irfan K | C36: Importance of IT Support in Organizations | F36: 1
A37: TDAR014 | B37: Nihal Roshan | C37: Django - Django REST framework | F37: 1
A38: TDAR015 | B38: Fadhil | C38: Deepfake Technology: Benefits and Risks | D38: 46213 | F38: 1
A39: TDAR016 | B39: Abdul Sabith SB | C39: HTML | D39: 46220 | F39: 1
A40: TDAR017 | B40: Abu Hashim | C40: Digital Banking and FinTech Innovation | F40: 1
...

Sheet Students Review
A1: SI No | B1: Course Name | C1: Name | D1: Review Date | E1: Mark | F1: Review Date | G1: Mark | H1: Review Date | I1: Mark | J1: Review Date | K1: Mark
A2: 1 | B2: MERN | C2: Abinav | D2: 09/06 - based | E2: - | F2: 18/6 - based | G2: 5 | H2: 46206 | I2: 8 | J2: 46232 | K2: 8.8 | L2: 46246 | M2: 8
A3: 2 | B3: MERN | C3: Aswin | D3: 09/06 - based | E3: - | F3: 18/6 - based | G3: - | H3: 46206 | I3: 8 | J3: 46232 | K3: 7 | L3: 46246 | M3: 10
A4: 3 | B4: MERN | C4: Harshal | D4: 09/06 - based | E4: 6 | F4: 18/6 - based | G4: 2.5 | H4: 46216 | I4: 7.5 | J4: 46234 | K4: AB
A5: 4 | B5: MERN | C5: Hisham | D5: 09/06 - based | E5: 5 | F5: 18/6 - based | H5: 46218 | I5: AB | J5: 46233 | K5: 5
A6: 5 | B6: MERN | C6: M Nasif | D6: 09/06 - based | F6: 18/6 - based | H6: 46223 | I6: AB | J6: 46232 | K6: 6.5
A7: 6 | B7: MERN | C7: M Sinan | D7: 09/06 - based | F7: 18/6 - based | H7: 46218 | I7: 6 | J7: 46233 | K7: 7.3
A8: 7 | B8: MERN | C8: M. Danish | D8: 09/06 - based | F8: 18/6 - based | H8: 46212 | I8: 5 | J8: 46232 | K8: AB
A9: 8 | B9: MERN | C9: M. Safeer | D9: 09/06 - based | E9: 7 | F9: 18/6 - based | H9: 46218 | I9: 5 | J9: 46231 | K9: 8
A10: 9 | B10: MERN | C10: Nibrasul Haqu | D10: 09/06 - based | E10: 6 | F10: 18/6 - based | G10: 2 | J10: 46232 | K10: 7.5
A11: 10 | B11: MERN | C11: Rahees PK | D11: 09/06 - based | E11: 5 | F11: 18/6 - based
A12: 11 | B12: python | C12: Safwan | D12: 09/06 - based | E12: - | F12: 18/6 - based | H12: 46230 | I12: 8
A13: 12 | B13: python | C13: Suhail | D13: 09/06 - based | E13: - | F13: 18/6 - based | H13: 46230 | I13: 7.5
A14: 13 | B14: python flutter | C14: Ameesha | D14: 09/06 - based | E14: 5 | F14: 18/6 - based | G14: 3
A15: 14 | B15: python flutter | C15: Hudha Reem | D15: 09/06 - based | E15: 7.5 | F15: 18/6 - based | H15: 46220 | I15: 6.5 | J15: 46239
A16: 15 | B16: python flutter | C16: M Munaver | D16: 09/06 - based | E16: - | F16: 18/6 - based | H16: 46219 | I16: 5.5
A17: 16 | B17: python flutter | C17: M.Shebil | D17: 09/06 - based | E17: - | F17: 18/6 - based
A18: 17 | B18: python flutter | C18: Muhammed Shahid | D18: 09/06 - based | E18: 7 | F18: 18/6 - based | H18: 46220 | I18: 7.75 | J18: 46239
A19: 18 | B19: Python Next js | C19: M. Shabeeb | D19: 09/06 - based | E19: - | F19: 18/6 - based | G19: 7 | H19: 46220 | I19: 6.5 | J19: 46227 | K19: 8 | L19: 46247
A20: 19 | B20: PythonDjango-Angular | C20: Ajmal | D20: 09/06 - based | E20: 7 | F20: 18/6 - based | G20: RS | H20: 46218 | I20: 7
A21: 20 | B21: PythonDjango-Angular | C21: Ameera K | D21: 09/06 - based | E21: - | F21: 18/6 - based | G21: 5.5
A22: 21 | B22: PythonDjango-Angular | C22: M Nidhal | D22: 09/06 - based | E22: 4 | F22: 18/6 - based | H22: 46220 | I22: 6 | J22: 46239 | K22: 7
A23: 22 | B23: PythonDjango-React | C23: Abdul Sabith SB | D23: 09/06 - based | E23: 3.5 | F23: 18/6 - based | G23: 8.5 | H23: 46219 | I23: AB | J23: 46246 | K23: AB
A24: 23 | B24: PythonDjango-React | C24: Abu Hashim | D24: 09/06 - based | E24: 0.5 | F24: 18/6 - based
A25: 24 | B25: PythonDjango-React | C25: Aflah KT | D25: 09/06 - based | E25: - | F25: 18/6 - based
A26: 25 | B26: PythonDjango-React | C26: Anas | D26: 09/06 - based | E26: - | F26: 18/6 - based | H26: 46212
A27: 26 | B27: PythonDjango-React | C27: Ashil | D27: 09/06 - based | E27: RS | F27: 18/6 - based | G27: 6.75 | H27: 46219 | I27: 4 | J27: 46245 | K27: 1.5
A28: 27 | B28: PythonDjango-React | C28: Fadhil | D28: 09/06 - based | E28: RS | F28: 18/6 - based | H28: 46216
A29: 28 | B29: PythonDjango-React | C29: Fidha Jebin | D29: 09/06 - based | E29: 7.5 | F29: 18/6 - based | H29: 46218 | I29: 8 | J29: 46239 | K29: AB
A30: 29 | B30: PythonDjango-React | C30: Jabir Ali | D30: 09/06 - based | E30: 4 | F30: 18/6 - based | H30: 46218 | I30: AB | J30: 46245 | K30: 7
A31: 30 | B31: PythonDjango-React | C31: Jithin | D31: 09/06 - based | E31: 7 | F31: 18/6 - based | G31: 3
A32: 31 | B32: PythonDjango-React | C32: M Dilshad | D32: 09/06 - based | E32: - | F32: 18/6 - based | G32: -
A33: 32 | B33: PythonDjango-React | C33: M Shameel | D33: 09/06 - based | E33: - | F33: 18/6 - based | G33: 8 | H33: 46221
A34: 33 | B34: PythonDjango-React | C34: M. Ajmal CP | D34: 09/06 - based | E34: 4 | F34: 18/6 - based | J34: 46245 | K34: 7
A35: 34 | B35: PythonDjango-React | C35: M. Irfan H | D35: 09/06 - based | E35: 8 | F35: 18/6 - based | H35: 46238 | I35: 6.5 | J35: 46246 | K35: 8
A36: 35 | B36: PythonDjango-React | C36: M. Irfan K | D36: 09/06 - based | E36: 4 | F36: 18/6 - based | G36: 7 | H36: 46231 | I36: 7.5
A37: 36 | B37: PythonDjango-React | C37: M. Jamshid | D37: 09/06 - based | E37: RS | F37: 18/6 - based | G37: 4.5 | H37: 46224 | I37: 4
A38: 37 | B38: PythonDjango-React | C38: M. Muaad | D38: 09/06 - based | E38: 6 | F38: 18/6 - based | G38: 5 | H38: 46211 | I38: 7 | J38: 46225 | K38: 8
A39: 38 | B39: PythonDjango-React | C39: M. Nihal | D39: 09/06 - based | E39: - | F39: 18/6 - based | H39: 46231
A40: 39 | B40: PythonDjango-React | C40: M. Rameesh KP | D40: 09/06 - based | E40: 3 | F40: 18/6 - based | H40: 46238 | I40: 6
...

Sheet WEEK Back
A1: No | B1: Name | C1: Date | D1: Mark | E1: Date | F1: Mark | G1: Date | H1: Mark | I1: Date | J1: Mark
A2: 1 | B2: Nihal Roshan | C2: 46220 | D2: AB | E2: 46211 | F2: 6 | G2: 18/6 - based | H2: 5 | I2: 09/06 - based | J2: 5
A3: 2 | B3: M Nidhal | C3: 46220 | D3: 6 | E3: 09/06 - based | F3: 4
A4: 3 | B4: Ashil | C4: 46219 | D4: 4 | E4: 18/6 - based | F4: 6.75
A5: 4 | B5: M Sinan | C5: 46218 | D5: 6
A6: 5 | B6: M. Danish | C6: 46212 | D6: 5
A7: 6 | B7: M. Safeer | C7: 46218 | D7: 5
A8: 7 | B8: Hudha Reem | C8: 46220 | D8: 6.5
A9: 8 | B9: M. Shabeeb | C9: 46220 | D9: 6.5
A10: 9 | B10: Shiyas Ahmad | C10: 46218 | D10: 6
A11: 10 | B11: Sajeer Fasil | C11: 18/6 - based | D11: 5
A12: 11 | B12: Ameesha | C12: 18/6 - based | D12: 3
A13: 12 | B13: Nibrasul Haqu | C13: 18/6 - based | D13: 2
A14: 13 | B14: Hisham | C14: 09/06 - based | D14: 5
A15: 14 | B15: Abu Hashim | C15: 09/06 - based | D15: 0.5
A16: 15 | B16: Jabir Ali | C16: 09/06 - based | D16: 4
A17: 16 | B17: M. Ajmal CP | C17: 09/06 - based | D17: 4
A18: 17 | B18: M. Jamshid | C18: 18/6 - based | D18: 4.5
A19: 18 | B19: M. Rameesh KP | C19: 09/06 - based | D19: 3
A20: 19 | B20: M. Shamil TK | C20: 09/06 - based | D20: 3
A21: 20 | B21: Nabla | C21: 09/06 - based | D21: 5
A22: 21 | B22: Sinan | C22: 18/6 - based | D22: 3

Sheet July 30
A1: T2 - 1
A2: Name | B2: Course Name | C2: Current Topic | D2: Progress | E2: Validity | F2: Status
A3: Ajmal | B3: PythonDjango-Angular | C3: Completed | D3: Completed | E3: 46233 | F3: NOC | G3: Passed
A4: Rahees PK | B4: MERN | C4: Completed | D4: Completed | E4: 46233
A5: Hisham | B5: MERN | C5: Completed | D5: Completed | E5: 46233 | F5: NOC
A6: Harshal | B6: MERN | C6: Completed | D6: Completed | E6: 46233 | F6: NOC
A7: Fathima Rafa | B7: UX-React | C7: completed | D7: completed | E7: 46233 | F7: -
A8: F. Safna | B8: UX-React | C8: completed | D8: completed | E8: 46233 | F8: -
A9: Riswa Mehfin | B9: UX-React | C9: completed | D9: completed | E9: 46233 | F9: -
A10: Faheem | B10: UX-React | C10: completed | D10: completed | E10: 46233
A11: Sinan | B11: UX-React | C11: completed | D11: completed | E11: 46233
A12: M. Danish | B12: MERN | C12: mongodb | D12: Advanced query | E12: 46233 | F12: -
A13: M Shameel | B13: PythonDjango-React | C13: React | D13: completed | E13: 46233 | F13: NOC
A14: M. Shamil TK | B14: PythonDjango-React | C14: React | D14: completed | E14: 46233 | F14: NOC
A15: M. Muaad | B15: PythonDjango-React | C15: React | D15: completed | E15: 46233 | F15: NOC
A16: M. Nihal | B16: PythonDjango-React | C16: React | D16: completed | E16: 46233 | F16: NOC

Sheet Aug 15
A1: T3 - 1
A2: Name | B2: Course Name | C2: Current Topic | D2: Progress | E2: Validity | F2: status
A3: M. Ajmal CP | B3: PythonDjango-React | C3: react | D3: DOM | E3: 46249
A4: M. Rameesh KP | B4: PythonDjango-React | C4: react | D4: DOM | E4: 46249
A5: M. Irfan H | B5: PythonDjango-React | C5: react | D5: api f | E5: 46249
A6: M. Safeer | B6: MERN | C6: react | D6: react | E6: 46249
A7: Sajeer Fasil | B7: PythonDjango-React | C7: react | D7: router | E7: 46249
A8: Raneed | B8: PythonDjango-React | C8: react | D8: DOM | E8: 46249 | F8: NOC
A9: Ashil | B9: PythonDjango-React | C9: react | D9: DOM | E9: 46249 | F9: NOC
A10: Ameesha | B10: Flutter-Django | C10: Django | D10: Authentication | E10: 46249
A11: Nibrasul Haqu | B11: MERN | C11: React | D11: intro | E11: 46249
A12: Raashid | B12: PythonDjango-React | C12: React | D12: intro | E12: 46249
A14: M. Rameesh KP
A15: M. Irfan H
A16: Safeer
A17: Nibrasul Haqu

Sheet Aug 31
A1: T3 - 2
A2: Name | B2: Course Name | C2: Current Topic | D2: Progress | E2: Validity
A3: M. Jamshid | B3: PythonDjango-React | C3: html | D3: intro | E3: 46265
A4: M. Irfan K | B4: PythonDjango-React | C4: html | D4: intro | E4: 46265
A5: Nihal Roshan | B5: PythonDjango-React | C5: html | D5: intro | E5: 46265
A6: Fadhil | B6: PythonDjango-React | C6: html | D6: intro | E6: 46265
A7: Abdul Sabith SB | B7: PythonDjango-React | C7: html | D7: intro | E7: 46265
A8: Abu Hashim | B8: PythonDjango-React | C8: html | D8: intro | E8: 46265
A9: Nabla | B9: PythonDjango-React | C9: html | D9: intro | E9: 46265
A10: Fidha Jebin | B10: PythonDjango-React | C10: CSS | D10: start | E10: 46265
A11: Jabir Ali | B11: PythonDjango-React | C11: html | D11: intro | E11: 46265
A12: Irfan PC | B12: UX-React | C12: CSS | D12: last portion

Sheet Nov 10
A1: T1 - 2
A2: Name | B2: Course Name | C2: Current Topic | D2: Progress | E2: Validity
A3: Shiyas Ahmad | B3: PythonDjango-React | C3: django | D3: forms | E3: 46336
A4: Ameera K | B4: PythonDjango-Angular | C4: Python | D4: patterns | E4: 46336
A5: M Nidhal | B5: PythonDjango-Angular | C5: Python | D5: file handling | E5: 46337
A6: Shahid | B6: Python Flutter
A7: Huda Reema | B7: Python Flutter

Sheet Dec 31
A1: T1 - 2
A2: Name | B2: Course Name | C2: Current Topic | D2: Progress | E2: Validity
